[2020-08-13 14:58:39,277] - werkzeug - INFO -  * Running on http://127.0.0.1:5000/ (Press CTRL+C to quit)
[2020-08-13 15:00:14,263] - werkzeug - INFO -  * Running on http://127.0.0.1:5000/ (Press CTRL+C to quit)
[2020-08-13 15:00:36,732] - werkzeug - INFO -  * Running on http://127.0.0.1:5000/ (Press CTRL+C to quit)
[2020-08-13 15:00:41,978] - root - INFO - RESET-------------------------
[2020-08-13 15:00:41,978] - root - INFO - {'T1': 135, 'T2': 120}
[2020-08-13 15:00:41,978] - root - INFO - RESET-------------------------
[2020-08-13 15:00:41,979] - root - INFO - [
    {
        "Address": "5H.5H.LD5_test1",
        "CheckAddress": "",
        "CheckDataType": "",
        "CheckValue": "",
        "DataType": "float",
        "Value": "135"
    },
    {
        "Address": "5H.5H.LD5_test2",
        "CheckAddress": "",
        "CheckDataType": "",
        "CheckValue": "",
        "DataType": "float",
        "Value": "120"
    }
]
[2020-08-13 15:00:41,979] - root - INFO - b'"[\\n    {\\n        \\"Address\\": \\"5H.5H.LD5_test1\\",\\n        \\"CheckAddress\\": \\"\\",\\n        \\"CheckDataType\\": \\"\\",\\n        \\"CheckValue\\": \\"\\",\\n        \\"DataType\\": \\"float\\",\\n        \\"Value\\": \\"135\\"\\n    },\\n    {\\n        \\"Address\\": \\"5H.5H.LD5_test2\\",\\n        \\"CheckAddress\\": \\"\\",\\n        \\"CheckDataType\\": \\"\\",\\n        \\"CheckValue\\": \\"\\",\\n        \\"DataType\\": \\"float\\",\\n        \\"Value\\": \\"120\\"\\n    }\\n]"'
[2020-08-13 15:00:41,979] - root - ERROR - REST API Failed: (<class 'ValueError'>, ValueError("unknown url type: ''"), <traceback object at 0x116592e60>)
[2020-08-13 15:00:41,979] - app - ERROR - Exception on /api/hs/reset [POST]
Traceback (most recent call last):
  File "/usr/local/anaconda3/envs/intellia/lib/python3.7/site-packages/flask/app.py", line 2447, in wsgi_app
    response = self.full_dispatch_request()
  File "/usr/local/anaconda3/envs/intellia/lib/python3.7/site-packages/flask/app.py", line 1952, in full_dispatch_request
    rv = self.handle_user_exception(e)
  File "/usr/local/anaconda3/envs/intellia/lib/python3.7/site-packages/flask/app.py", line 1821, in handle_user_exception
    reraise(exc_type, exc_value, tb)
  File "/usr/local/anaconda3/envs/intellia/lib/python3.7/site-packages/flask/_compat.py", line 39, in reraise
    raise value
  File "/usr/local/anaconda3/envs/intellia/lib/python3.7/site-packages/flask/app.py", line 1950, in full_dispatch_request
    rv = self.dispatch_request()
  File "/usr/local/anaconda3/envs/intellia/lib/python3.7/site-packages/flask/app.py", line 1936, in dispatch_request
    return self.view_functions[rule.endpoint](**req.view_args)
  File "/Users/bytedance/PycharmProjects/ml_model/app.py", line 26, in manual_reset_api
    res = reset_test([str(T1), str(T2)])
  File "/Users/bytedance/PycharmProjects/ml_model/model/hs.py", line 38, in reset_test
    res = json.loads(res.decode())
AttributeError: 'str' object has no attribute 'decode'
[2020-08-13 15:00:41,983] - werkzeug - INFO - 127.0.0.1 - - [13/Aug/2020 15:00:41] "[35m[1mPOST /api/hs/reset HTTP/1.1[0m" 500 -
[2020-08-13 15:04:00,810] - werkzeug - INFO -  * Running on http://127.0.0.1:5000/ (Press CTRL+C to quit)
[2020-08-13 15:04:29,719] - werkzeug - INFO -  * Running on http://127.0.0.1:5000/ (Press CTRL+C to quit)
[2020-08-13 15:05:42,171] - werkzeug - INFO -  * Running on http://127.0.0.1:5000/ (Press CTRL+C to quit)
[2020-08-13 15:06:15,262] - werkzeug - INFO -  * Running on http://127.0.0.1:5000/ (Press CTRL+C to quit)
[2020-08-13 15:06:59,915] - werkzeug - INFO -  * Running on http://127.0.0.1:5000/ (Press CTRL+C to quit)
[2020-08-13 15:07:29,979] - werkzeug - INFO -  * Running on http://127.0.0.1:5000/ (Press CTRL+C to quit)
[2020-08-13 15:08:23,308] - werkzeug - INFO -  * Running on http://127.0.0.1:5000/ (Press CTRL+C to quit)
[2020-08-13 15:08:28,574] - root - INFO - [
    {
        "Address": "5H.5H.LD5_test1",
        "CheckAddress": "",
        "CheckDataType": "",
        "CheckValue": "",
        "DataType": "float",
        "Value": "135"
    },
    {
        "Address": "5H.5H.LD5_test2",
        "CheckAddress": "",
        "CheckDataType": "",
        "CheckValue": "",
        "DataType": "float",
        "Value": "120"
    }
]
[2020-08-13 15:08:28,575] - root - INFO - b'"[\\n    {\\n        \\"Address\\": \\"5H.5H.LD5_test1\\",\\n        \\"CheckAddress\\": \\"\\",\\n        \\"CheckDataType\\": \\"\\",\\n        \\"CheckValue\\": \\"\\",\\n        \\"DataType\\": \\"float\\",\\n        \\"Value\\": \\"135\\"\\n    },\\n    {\\n        \\"Address\\": \\"5H.5H.LD5_test2\\",\\n        \\"CheckAddress\\": \\"\\",\\n        \\"CheckDataType\\": \\"\\",\\n        \\"CheckValue\\": \\"\\",\\n        \\"DataType\\": \\"float\\",\\n        \\"Value\\": \\"120\\"\\n    }\\n]"'
[2020-08-13 15:08:28,575] - root - ERROR - REST API Failed: (<class 'ValueError'>, ValueError("unknown url type: ''"), <traceback object at 0x10ff85f50>)
[2020-08-13 15:08:28,575] - app - ERROR - Exception on /api/hs/reset [POST]
Traceback (most recent call last):
  File "/usr/local/anaconda3/envs/intellia/lib/python3.7/site-packages/flask/app.py", line 2447, in wsgi_app
    response = self.full_dispatch_request()
  File "/usr/local/anaconda3/envs/intellia/lib/python3.7/site-packages/flask/app.py", line 1952, in full_dispatch_request
    rv = self.handle_user_exception(e)
  File "/usr/local/anaconda3/envs/intellia/lib/python3.7/site-packages/flask/app.py", line 1821, in handle_user_exception
    reraise(exc_type, exc_value, tb)
  File "/usr/local/anaconda3/envs/intellia/lib/python3.7/site-packages/flask/_compat.py", line 39, in reraise
    raise value
  File "/usr/local/anaconda3/envs/intellia/lib/python3.7/site-packages/flask/app.py", line 1950, in full_dispatch_request
    rv = self.dispatch_request()
  File "/usr/local/anaconda3/envs/intellia/lib/python3.7/site-packages/flask/app.py", line 1936, in dispatch_request
    return self.view_functions[rule.endpoint](**req.view_args)
  File "/Users/bytedance/PycharmProjects/ml_model/app.py", line 25, in manual_reset_api
    res = reset_test([str(T1), str(T2)])
  File "/Users/bytedance/PycharmProjects/ml_model/model/hs.py", line 38, in reset_test
    res = json.loads(res.decode())
AttributeError: 'str' object has no attribute 'decode'
[2020-08-13 15:08:28,576] - werkzeug - INFO - 127.0.0.1 - - [13/Aug/2020 15:08:28] "[35m[1mPOST /api/hs/reset HTTP/1.1[0m" 500 -
[2020-08-13 15:12:11,515] - werkzeug - INFO -  * Running on http://127.0.0.1:5000/ (Press CTRL+C to quit)
[2020-08-13 15:12:45,332] - werkzeug - INFO -  * Running on http://127.0.0.1:5000/ (Press CTRL+C to quit)
[2020-08-13 15:12:58,314] - werkzeug - INFO -  * Running on http://127.0.0.1:8888/ (Press CTRL+C to quit)
[2020-08-13 15:13:05,252] - root - INFO - [
    {
        "Address": "5H.5H.LD5_test1",
        "CheckAddress": "",
        "CheckDataType": "",
        "CheckValue": "",
        "DataType": "float",
        "Value": "135"
    },
    {
        "Address": "5H.5H.LD5_test2",
        "CheckAddress": "",
        "CheckDataType": "",
        "CheckValue": "",
        "DataType": "float",
        "Value": "120"
    }
]
[2020-08-13 15:13:05,252] - root - INFO - b'"[\\n    {\\n        \\"Address\\": \\"5H.5H.LD5_test1\\",\\n        \\"CheckAddress\\": \\"\\",\\n        \\"CheckDataType\\": \\"\\",\\n        \\"CheckValue\\": \\"\\",\\n        \\"DataType\\": \\"float\\",\\n        \\"Value\\": \\"135\\"\\n    },\\n    {\\n        \\"Address\\": \\"5H.5H.LD5_test2\\",\\n        \\"CheckAddress\\": \\"\\",\\n        \\"CheckDataType\\": \\"\\",\\n        \\"CheckValue\\": \\"\\",\\n        \\"DataType\\": \\"float\\",\\n        \\"Value\\": \\"120\\"\\n    }\\n]"'
[2020-08-13 15:13:05,252] - root - ERROR - REST API Failed: (<class 'ValueError'>, ValueError("unknown url type: ''"), <traceback object at 0x11dbb3f00>)
[2020-08-13 15:13:05,252] - app - ERROR - Exception on /api/hs/reset [POST]
Traceback (most recent call last):
  File "/usr/local/anaconda3/envs/intellia/lib/python3.7/site-packages/flask/app.py", line 2447, in wsgi_app
    response = self.full_dispatch_request()
  File "/usr/local/anaconda3/envs/intellia/lib/python3.7/site-packages/flask/app.py", line 1952, in full_dispatch_request
    rv = self.handle_user_exception(e)
  File "/usr/local/anaconda3/envs/intellia/lib/python3.7/site-packages/flask/app.py", line 1821, in handle_user_exception
    reraise(exc_type, exc_value, tb)
  File "/usr/local/anaconda3/envs/intellia/lib/python3.7/site-packages/flask/_compat.py", line 39, in reraise
    raise value
  File "/usr/local/anaconda3/envs/intellia/lib/python3.7/site-packages/flask/app.py", line 1950, in full_dispatch_request
    rv = self.dispatch_request()
  File "/usr/local/anaconda3/envs/intellia/lib/python3.7/site-packages/flask/app.py", line 1936, in dispatch_request
    return self.view_functions[rule.endpoint](**req.view_args)
  File "/Users/bytedance/PycharmProjects/ml_model/app.py", line 25, in manual_reset_api
    res = reset_test([str(T1), str(T2)])
  File "/Users/bytedance/PycharmProjects/ml_model/model/hs.py", line 38, in reset_test
    res = json.loads(res.decode())
AttributeError: 'str' object has no attribute 'decode'
[2020-08-13 15:13:05,254] - werkzeug - INFO - 127.0.0.1 - - [13/Aug/2020 15:13:05] "[35m[1mPOST /api/hs/reset HTTP/1.1[0m" 500 -
[2020-08-13 15:15:43,485] - werkzeug - INFO -  * Running on http://127.0.0.1:8888/ (Press CTRL+C to quit)
[2020-08-13 15:15:46,951] - root - INFO - RESET-------------------------
[2020-08-13 15:15:46,951] - root - INFO - {'T1': 135, 'T2': 120}
[2020-08-13 15:15:46,951] - root - INFO - RESET-------------------------
[2020-08-13 15:15:46,952] - root - INFO - [
    {
        "Address": "5H.5H.LD5_test1",
        "CheckAddress": "",
        "CheckDataType": "",
        "CheckValue": "",
        "DataType": "float",
        "Value": "135"
    },
    {
        "Address": "5H.5H.LD5_test2",
        "CheckAddress": "",
        "CheckDataType": "",
        "CheckValue": "",
        "DataType": "float",
        "Value": "120"
    }
]
[2020-08-13 15:15:46,952] - root - INFO - b'"[\\n    {\\n        \\"Address\\": \\"5H.5H.LD5_test1\\",\\n        \\"CheckAddress\\": \\"\\",\\n        \\"CheckDataType\\": \\"\\",\\n        \\"CheckValue\\": \\"\\",\\n        \\"DataType\\": \\"float\\",\\n        \\"Value\\": \\"135\\"\\n    },\\n    {\\n        \\"Address\\": \\"5H.5H.LD5_test2\\",\\n        \\"CheckAddress\\": \\"\\",\\n        \\"CheckDataType\\": \\"\\",\\n        \\"CheckValue\\": \\"\\",\\n        \\"DataType\\": \\"float\\",\\n        \\"Value\\": \\"120\\"\\n    }\\n]"'
[2020-08-13 15:15:46,952] - root - ERROR - REST API Failed: (<class 'ValueError'>, ValueError("unknown url type: ''"), <traceback object at 0x117422e10>)
[2020-08-13 15:15:46,953] - app - ERROR - Exception on /api/hs/reset [POST]
Traceback (most recent call last):
  File "/usr/local/anaconda3/envs/intellia/lib/python3.7/site-packages/flask/app.py", line 2447, in wsgi_app
    response = self.full_dispatch_request()
  File "/usr/local/anaconda3/envs/intellia/lib/python3.7/site-packages/flask/app.py", line 1952, in full_dispatch_request
    rv = self.handle_user_exception(e)
  File "/usr/local/anaconda3/envs/intellia/lib/python3.7/site-packages/flask/app.py", line 1821, in handle_user_exception
    reraise(exc_type, exc_value, tb)
  File "/usr/local/anaconda3/envs/intellia/lib/python3.7/site-packages/flask/_compat.py", line 39, in reraise
    raise value
  File "/usr/local/anaconda3/envs/intellia/lib/python3.7/site-packages/flask/app.py", line 1950, in full_dispatch_request
    rv = self.dispatch_request()
  File "/usr/local/anaconda3/envs/intellia/lib/python3.7/site-packages/flask/app.py", line 1936, in dispatch_request
    return self.view_functions[rule.endpoint](**req.view_args)
  File "/Users/bytedance/PycharmProjects/ml_model/app.py", line 25, in manual_reset_api
    res = reset_test([str(T1), str(T2)])
  File "/Users/bytedance/PycharmProjects/ml_model/model/hs.py", line 39, in reset_test
    res = json.loads(res.decode())
AttributeError: 'str' object has no attribute 'decode'
[2020-08-13 15:15:46,958] - werkzeug - INFO - 127.0.0.1 - - [13/Aug/2020 15:15:46] "[35m[1mPOST /api/hs/reset HTTP/1.1[0m" 500 -
[2020-08-13 15:16:52,058] - werkzeug - INFO -  * Running on http://127.0.0.1:8888/ (Press CTRL+C to quit)
[2020-08-13 15:16:54,585] - root - INFO - RESET-------------------------
[2020-08-13 15:16:54,585] - root - INFO - {'T1': 135, 'T2': 120}
[2020-08-13 15:16:54,586] - root - INFO - RESET-------------------------
[2020-08-13 15:16:54,586] - root - INFO - [
    {
        "Address": "5H.5H.LD5_test1",
        "CheckAddress": "",
        "CheckDataType": "",
        "CheckValue": "",
        "DataType": "float",
        "Value": "135"
    },
    {
        "Address": "5H.5H.LD5_test2",
        "CheckAddress": "",
        "CheckDataType": "",
        "CheckValue": "",
        "DataType": "float",
        "Value": "120"
    }
]
[2020-08-13 15:16:54,586] - root - INFO - b'"[\\n    {\\n        \\"Address\\": \\"5H.5H.LD5_test1\\",\\n        \\"CheckAddress\\": \\"\\",\\n        \\"CheckDataType\\": \\"\\",\\n        \\"CheckValue\\": \\"\\",\\n        \\"DataType\\": \\"float\\",\\n        \\"Value\\": \\"135\\"\\n    },\\n    {\\n        \\"Address\\": \\"5H.5H.LD5_test2\\",\\n        \\"CheckAddress\\": \\"\\",\\n        \\"CheckDataType\\": \\"\\",\\n        \\"CheckValue\\": \\"\\",\\n        \\"DataType\\": \\"float\\",\\n        \\"Value\\": \\"120\\"\\n    }\\n]"'
[2020-08-13 15:16:54,586] - root - ERROR - REST API Failed: (<class 'ValueError'>, ValueError("unknown url type: ''"), <traceback object at 0x115efeeb0>)
[2020-08-13 15:16:54,586] - root - INFO - None
[2020-08-13 15:16:54,586] - app - ERROR - Exception on /api/hs/reset [POST]
Traceback (most recent call last):
  File "/usr/local/anaconda3/envs/intellia/lib/python3.7/site-packages/flask/app.py", line 2447, in wsgi_app
    response = self.full_dispatch_request()
  File "/usr/local/anaconda3/envs/intellia/lib/python3.7/site-packages/flask/app.py", line 1953, in full_dispatch_request
    return self.finalize_request(rv)
  File "/usr/local/anaconda3/envs/intellia/lib/python3.7/site-packages/flask/app.py", line 1968, in finalize_request
    response = self.make_response(rv)
  File "/usr/local/anaconda3/envs/intellia/lib/python3.7/site-packages/flask/app.py", line 2098, in make_response
    "The view function did not return a valid response. The"
TypeError: The view function did not return a valid response. The function either returned None or ended without a return statement.
[2020-08-13 15:16:54,587] - werkzeug - INFO - 127.0.0.1 - - [13/Aug/2020 15:16:54] "[35m[1mPOST /api/hs/reset HTTP/1.1[0m" 500 -
[2020-08-13 15:17:09,168] - werkzeug - INFO -  * Running on http://127.0.0.1:8888/ (Press CTRL+C to quit)
[2020-08-13 15:17:14,996] - root - INFO - RESET-------------------------
[2020-08-13 15:17:14,996] - root - INFO - {'T1': 135, 'T2': 120}
[2020-08-13 15:17:14,996] - root - INFO - RESET-------------------------
[2020-08-13 15:17:14,997] - root - INFO - [
    {
        "Address": "5H.5H.LD5_test1",
        "CheckAddress": "",
        "CheckDataType": "",
        "CheckValue": "",
        "DataType": "float",
        "Value": "135"
    },
    {
        "Address": "5H.5H.LD5_test2",
        "CheckAddress": "",
        "CheckDataType": "",
        "CheckValue": "",
        "DataType": "float",
        "Value": "120"
    }
]
[2020-08-13 15:17:14,997] - root - INFO - b'"[\\n    {\\n        \\"Address\\": \\"5H.5H.LD5_test1\\",\\n        \\"CheckAddress\\": \\"\\",\\n        \\"CheckDataType\\": \\"\\",\\n        \\"CheckValue\\": \\"\\",\\n        \\"DataType\\": \\"float\\",\\n        \\"Value\\": \\"135\\"\\n    },\\n    {\\n        \\"Address\\": \\"5H.5H.LD5_test2\\",\\n        \\"CheckAddress\\": \\"\\",\\n        \\"CheckDataType\\": \\"\\",\\n        \\"CheckValue\\": \\"\\",\\n        \\"DataType\\": \\"float\\",\\n        \\"Value\\": \\"120\\"\\n    }\\n]"'
[2020-08-13 15:17:14,997] - root - ERROR - REST API Failed: (<class 'ValueError'>, ValueError("unknown url type: ''"), <traceback object at 0x110877eb0>)
[2020-08-13 15:17:14,997] - root - INFO - None
[2020-08-13 15:17:14,997] - app - ERROR - Exception on /api/hs/reset [POST]
Traceback (most recent call last):
  File "/usr/local/anaconda3/envs/intellia/lib/python3.7/site-packages/flask/app.py", line 2447, in wsgi_app
    response = self.full_dispatch_request()
  File "/usr/local/anaconda3/envs/intellia/lib/python3.7/site-packages/flask/app.py", line 1953, in full_dispatch_request
    return self.finalize_request(rv)
  File "/usr/local/anaconda3/envs/intellia/lib/python3.7/site-packages/flask/app.py", line 1968, in finalize_request
    response = self.make_response(rv)
  File "/usr/local/anaconda3/envs/intellia/lib/python3.7/site-packages/flask/app.py", line 2098, in make_response
    "The view function did not return a valid response. The"
TypeError: The view function did not return a valid response. The function either returned None or ended without a return statement.
[2020-08-13 15:17:14,999] - werkzeug - INFO - 127.0.0.1 - - [13/Aug/2020 15:17:14] "[35m[1mPOST /api/hs/reset HTTP/1.1[0m" 500 -
[2020-08-13 15:17:28,304] - werkzeug - INFO -  * Running on http://127.0.0.1:8888/ (Press CTRL+C to quit)
[2020-08-13 15:17:32,951] - root - INFO - RESET-------------------------
[2020-08-13 15:17:32,951] - root - INFO - {'T1': 135, 'T2': 120}
[2020-08-13 15:17:32,951] - root - INFO - RESET-------------------------
[2020-08-13 15:17:32,952] - root - INFO - [
    {
        "Address": "5H.5H.LD5_test1",
        "CheckAddress": "",
        "CheckDataType": "",
        "CheckValue": "",
        "DataType": "float",
        "Value": "135"
    },
    {
        "Address": "5H.5H.LD5_test2",
        "CheckAddress": "",
        "CheckDataType": "",
        "CheckValue": "",
        "DataType": "float",
        "Value": "120"
    }
]
[2020-08-13 15:17:32,952] - root - INFO - b'"[\\n    {\\n        \\"Address\\": \\"5H.5H.LD5_test1\\",\\n        \\"CheckAddress\\": \\"\\",\\n        \\"CheckDataType\\": \\"\\",\\n        \\"CheckValue\\": \\"\\",\\n        \\"DataType\\": \\"float\\",\\n        \\"Value\\": \\"135\\"\\n    },\\n    {\\n        \\"Address\\": \\"5H.5H.LD5_test2\\",\\n        \\"CheckAddress\\": \\"\\",\\n        \\"CheckDataType\\": \\"\\",\\n        \\"CheckValue\\": \\"\\",\\n        \\"DataType\\": \\"float\\",\\n        \\"Value\\": \\"120\\"\\n    }\\n]"'
[2020-08-13 15:17:32,952] - root - ERROR - REST API Failed: (<class 'ValueError'>, ValueError("unknown url type: ''"), <traceback object at 0x11e5fdeb0>)
[2020-08-13 15:17:32,952] - root - INFO - None
[2020-08-13 15:17:32,952] - app - ERROR - Exception on /api/hs/reset [POST]
Traceback (most recent call last):
  File "/usr/local/anaconda3/envs/intellia/lib/python3.7/site-packages/flask/app.py", line 2447, in wsgi_app
    response = self.full_dispatch_request()
  File "/usr/local/anaconda3/envs/intellia/lib/python3.7/site-packages/flask/app.py", line 1953, in full_dispatch_request
    return self.finalize_request(rv)
  File "/usr/local/anaconda3/envs/intellia/lib/python3.7/site-packages/flask/app.py", line 1968, in finalize_request
    response = self.make_response(rv)
  File "/usr/local/anaconda3/envs/intellia/lib/python3.7/site-packages/flask/app.py", line 2098, in make_response
    "The view function did not return a valid response. The"
TypeError: The view function did not return a valid response. The function either returned None or ended without a return statement.
[2020-08-13 15:17:32,953] - werkzeug - INFO - 127.0.0.1 - - [13/Aug/2020 15:17:32] "[35m[1mPOST /api/hs/reset HTTP/1.1[0m" 500 -
[2020-08-13 15:27:04,221] - werkzeug - INFO -  * Running on http://127.0.0.1:8888/ (Press CTRL+C to quit)
[2020-08-13 15:27:09,227] - root - INFO - RESET-------------------------
[2020-08-13 15:27:09,227] - root - INFO - {'T1': 135, 'T2': 120}
[2020-08-13 15:27:09,228] - root - INFO - RESET-------------------------
[2020-08-13 15:27:09,228] - root - INFO - [
    {
        "Address": "5H.5H.LD5_test1",
        "CheckAddress": "",
        "CheckDataType": "",
        "CheckValue": "",
        "DataType": "float",
        "Value": "135"
    },
    {
        "Address": "5H.5H.LD5_test2",
        "CheckAddress": "",
        "CheckDataType": "",
        "CheckValue": "",
        "DataType": "float",
        "Value": "120"
    }
]
[2020-08-13 15:27:09,228] - root - INFO - b'"[\\n    {\\n        \\"Address\\": \\"5H.5H.LD5_test1\\",\\n        \\"CheckAddress\\": \\"\\",\\n        \\"CheckDataType\\": \\"\\",\\n        \\"CheckValue\\": \\"\\",\\n        \\"DataType\\": \\"float\\",\\n        \\"Value\\": \\"135\\"\\n    },\\n    {\\n        \\"Address\\": \\"5H.5H.LD5_test2\\",\\n        \\"CheckAddress\\": \\"\\",\\n        \\"CheckDataType\\": \\"\\",\\n        \\"CheckValue\\": \\"\\",\\n        \\"DataType\\": \\"float\\",\\n        \\"Value\\": \\"120\\"\\n    }\\n]"'
[2020-08-13 15:28:24,841] - root - ERROR - REST API Failed: (<class 'urllib.error.URLError'>, URLError(TimeoutError(60, 'Operation timed out')), <traceback object at 0x115cfecd0>)
[2020-08-13 15:28:24,841] - app - ERROR - Exception on /api/hs/reset [POST]
Traceback (most recent call last):
  File "/usr/local/anaconda3/envs/intellia/lib/python3.7/site-packages/flask/app.py", line 2447, in wsgi_app
    response = self.full_dispatch_request()
  File "/usr/local/anaconda3/envs/intellia/lib/python3.7/site-packages/flask/app.py", line 1952, in full_dispatch_request
    rv = self.handle_user_exception(e)
  File "/usr/local/anaconda3/envs/intellia/lib/python3.7/site-packages/flask/app.py", line 1821, in handle_user_exception
    reraise(exc_type, exc_value, tb)
  File "/usr/local/anaconda3/envs/intellia/lib/python3.7/site-packages/flask/_compat.py", line 39, in reraise
    raise value
  File "/usr/local/anaconda3/envs/intellia/lib/python3.7/site-packages/flask/app.py", line 1950, in full_dispatch_request
    rv = self.dispatch_request()
  File "/usr/local/anaconda3/envs/intellia/lib/python3.7/site-packages/flask/app.py", line 1936, in dispatch_request
    return self.view_functions[rule.endpoint](**req.view_args)
  File "/Users/bytedance/PycharmProjects/ml_model/app.py", line 25, in manual_reset_api
    res = reset_test([str(T1), str(T2)])
  File "/Users/bytedance/PycharmProjects/ml_model/model/hs.py", line 43, in reset_test
    return None if _is_failure(res) else json.loads(res.decode())
AttributeError: 'str' object has no attribute 'decode'
[2020-08-13 15:28:24,845] - werkzeug - INFO - 127.0.0.1 - - [13/Aug/2020 15:28:24] "[35m[1mPOST /api/hs/reset HTTP/1.1[0m" 500 -
[2020-08-13 15:40:37,957] - werkzeug - INFO -  * Running on http://127.0.0.1:8888/ (Press CTRL+C to quit)
[2020-08-13 15:40:41,439] - root - INFO - HS RESET-------------------------
[2020-08-13 15:40:41,439] - root - INFO - {'T1': 135, 'T2': 120}
[2020-08-13 15:40:41,439] - root - INFO - HS RESET-------------------------
[2020-08-13 15:40:41,439] - root - INFO - [
    {
        "Address": "5H.5H.LD5_test1",
        "CheckAddress": "",
        "CheckDataType": "",
        "CheckValue": "",
        "DataType": "float",
        "Value": "135"
    },
    {
        "Address": "5H.5H.LD5_test2",
        "CheckAddress": "",
        "CheckDataType": "",
        "CheckValue": "",
        "DataType": "float",
        "Value": "120"
    }
]
[2020-08-13 15:40:41,440] - root - INFO - b'"[\\n    {\\n        \\"Address\\": \\"5H.5H.LD5_test1\\",\\n        \\"CheckAddress\\": \\"\\",\\n        \\"CheckDataType\\": \\"\\",\\n        \\"CheckValue\\": \\"\\",\\n        \\"DataType\\": \\"float\\",\\n        \\"Value\\": \\"135\\"\\n    },\\n    {\\n        \\"Address\\": \\"5H.5H.LD5_test2\\",\\n        \\"CheckAddress\\": \\"\\",\\n        \\"CheckDataType\\": \\"\\",\\n        \\"CheckValue\\": \\"\\",\\n        \\"DataType\\": \\"float\\",\\n        \\"Value\\": \\"120\\"\\n    }\\n]"'
